<sdf version='1.10'>
  <world name='empty'>
    <physics name='1ms' type='ignored'>
      <max_step_size>0.001</max_step_size>
      <real_time_factor>1</real_time_factor>
      <real_time_update_rate>1000</real_time_update_rate>
    </physics>
    <plugin name='gz::sim::systems::Physics' filename='gz-sim-physics-system'/>
    <plugin name='gz::sim::systems::UserCommands' filename='gz-sim-user-commands-system'/>
    <plugin name='gz::sim::systems::SceneBroadcaster' filename='gz-sim-scene-broadcaster-system'/>
    <plugin name='gz::sim::systems::Contact' filename='gz-sim-contact-system'/>
    <plugin name='gz::sim::systems::Sensors' filename='gz-sim-sensors-system'>
      <render_engine>ogre2</render_engine>
    </plugin>
    <gravity>0 0 -9.8000000000000007</gravity>
    <magnetic_field>5.5644999999999998e-06 2.2875799999999999e-05 -4.2388400000000002e-05</magnetic_field>
    <atmosphere type='adiabatic'/>
    <scene>
      <ambient>0.400000006 0.400000006 0.400000006 1</ambient>
      <background>0.699999988 0.699999988 0.699999988 1</background>
      <shadows>true</shadows>
    </scene>
    <model name='ground_plane'>
      <static>true</static>
      <link name='link'>
        <collision name='collision'>
          <geometry>
            <plane>
              <normal>0 0 1</normal>
              <size>100 100</size>
            </plane>
          </geometry>
          <surface>
            <friction>
              <ode/>
            </friction>
            <bounce/>
            <contact/>
          </surface>
        </collision>
        <visual name='visual'>
          <geometry>
            <plane>
              <normal>0 0 1</normal>
              <size>100 100</size>
            </plane>
          </geometry>
          <material>
            <ambient>0.800000012 0.800000012 0.800000012 1</ambient>
            <diffuse>0.800000012 0.800000012 0.800000012 1</diffuse>
            <specular>0.800000012 0.800000012 0.800000012 1</specular>
          </material>
        </visual>
        <pose>0 0 0 0 0 0</pose>
        <inertial>
          <pose>0 0 0 0 0 0</pose>
          <mass>1</mass>
          <inertia>
            <ixx>1</ixx>
            <ixy>0</ixy>
            <ixz>0</ixz>
            <iyy>1</iyy>
            <iyz>0</iyz>
            <izz>1</izz>
          </inertia>
        </inertial>
        <enable_wind>false</enable_wind>
      </link>
      <pose>0 0 0 0 0 0</pose>
      <self_collide>false</self_collide>
    </model>
    <model name='robot3'>
      <link name='base_footprint'>
        <inertial>
          <pose>0 0 0.10000000000000001 0 0 0</pose>
          <mass>1</mass>
          <inertia>
            <ixx>0.093333333333333324</ixx>
            <ixy>0</ixy>
            <ixz>0</ixz>
            <iyy>0.093333333333333324</iyy>
            <iyz>0</iyz>
            <izz>0.17999999999999999</izz>
          </inertia>
        </inertial>
        <collision name='base_footprint_fixed_joint_lump__base_link_collision'>
          <pose>0 0 0.10000000000000001 0 0 0</pose>
          <geometry>
            <cylinder>
              <length>0.20000000000000001</length>
              <radius>0.59999999999999998</radius>
            </cylinder>
          </geometry>
          <surface>
            <friction>
              <ode/>
            </friction>
            <bounce/>
            <contact/>
          </surface>
        </collision>
        <visual name='base_footprint_fixed_joint_lump__base_link_visual'>
          <pose>0 0 0.10000000000000001 0 0 0</pose>
          <geometry>
            <cylinder>
              <length>0.20000000000000001</length>
              <radius>0.59999999999999998</radius>
            </cylinder>
          </geometry>
          <material>
            <diffuse>0 1 0 1</diffuse>
            <ambient>0 1 0 1</ambient>
          </material>
        </visual>
        <pose>0 0 0 0 0 0</pose>
        <enable_wind>false</enable_wind>
      </link>
      <joint name='wheel_front_joint' type='revolute'>
        <pose>0 0 0 0 0 0</pose>
        <parent>base_footprint</parent>
        <child>wheel_front_link</child>
        <axis>
          <xyz>0 1 0</xyz>
          <limit>
            <lower>-inf</lower>
            <upper>inf</upper>
            <effort>inf</effort>
            <velocity>inf</velocity>
            <stiffness>100000000</stiffness>
            <dissipation>1</dissipation>
          </limit>
          <dynamics>
            <spring_reference>0</spring_reference>
            <spring_stiffness>0</spring_stiffness>
            <damping>0</damping>
            <friction>0</friction>
          </dynamics>
        </axis>
      </joint>
      <link name='wheel_front_link'>
        <pose>0 0.55000000000000004 1.3877787807814457e-17 0 1.5244579378465031e-15 1.5707963267948959</pose>
        <inertial>
          <pose>0 0 0 0 0 0</pose>
          <mass>0.5</mass>
          <inertia>
            <ixx>0.001</ixx>
            <ixy>0</ixy>
            <ixz>0</ixz>
            <iyy>0.001</iyy>
            <iyz>0</iyz>
            <izz>0.001</izz>
          </inertia>
        </inertial>
        <collision name='wheel_front_link_collision'>
          <pose>0 0 0 0 1.5707963267948966 0</pose>
          <geometry>
            <cylinder>
              <length>0.050000000000000003</length>
              <radius>0.10000000000000001</radius>
            </cylinder>
          </geometry>
          <surface>
            <friction>
              <ode/>
            </friction>
            <bounce/>
            <contact/>
          </surface>
        </collision>
        <visual name='wheel_front_link_visual'>
          <pose>0 0 0 0 1.5707963267948966 0</pose>
          <geometry>
            <cylinder>
              <length>0.050000000000000003</length>
              <radius>0.10000000000000001</radius>
            </cylinder>
          </geometry>
          <material>
            <diffuse>0.625 0.625 0.625 1</diffuse>
            <ambient>0.625 0.625 0.625 1</ambient>
          </material>
        </visual>
        <enable_wind>false</enable_wind>
      </link>
      <joint name='wheel_left_joint' type='revolute'>
        <pose>0 -2.7755575615628914e-17 0 0 0 0</pose>
        <parent>base_footprint</parent>
        <child>wheel_left_link</child>
        <axis>
          <xyz>0 1 0</xyz>
          <limit>
            <lower>-inf</lower>
            <upper>inf</upper>
            <effort>inf</effort>
            <velocity>inf</velocity>
            <stiffness>100000000</stiffness>
            <dissipation>1</dissipation>
          </limit>
          <dynamics>
            <spring_reference>0</spring_reference>
            <spring_stiffness>0</spring_stiffness>
            <damping>0</damping>
            <friction>0</friction>
          </dynamics>
        </axis>
      </joint>
      <link name='wheel_left_link'>
        <pose>-0.47631397208144133 -0.27500000000000013 1.3877787807814457e-17 -2.0029671421627253e-32 -2.6233784772205221e-17 -2.617993877991494</pose>
        <inertial>
          <pose>0 0 0 0 0 0</pose>
          <mass>0.5</mass>
          <inertia>
            <ixx>0.001</ixx>
            <ixy>0</ixy>
            <ixz>0</ixz>
            <iyy>0.001</iyy>
            <iyz>0</iyz>
            <izz>0.001</izz>
          </inertia>
        </inertial>
        <collision name='wheel_left_link_collision'>
          <pose>0 0 0 0 1.5707963267948966 0</pose>
          <geometry>
            <cylinder>
              <length>0.050000000000000003</length>
              <radius>0.10000000000000001</radius>
            </cylinder>
          </geometry>
          <surface>
            <friction>
              <ode/>
            </friction>
            <bounce/>
            <contact/>
          </surface>
        </collision>
        <visual name='wheel_left_link_visual'>
          <pose>0 0 0 0 1.5707963267948966 0</pose>
          <geometry>
            <cylinder>
              <length>0.050000000000000003</length>
              <radius>0.10000000000000001</radius>
            </cylinder>
          </geometry>
          <material>
            <diffuse>0.625 0.625 0.625 1</diffuse>
            <ambient>0.625 0.625 0.625 1</ambient>
          </material>
        </visual>
        <enable_wind>false</enable_wind>
      </link>
      <joint name='wheel_right_joint' type='revolute'>
        <pose>1.1102230246251565e-16 2.7755575615628914e-17 0 0 0 0</pose>
        <parent>base_footprint</parent>
        <child>wheel_right_link</child>
        <axis>
          <xyz>0 1 0</xyz>
          <limit>
            <lower>-inf</lower>
            <upper>inf</upper>
            <effort>inf</effort>
            <velocity>inf</velocity>
            <stiffness>100000000</stiffness>
            <dissipation>1</dissipation>
          </limit>
          <dynamics>
            <spring_reference>0</spring_reference>
            <spring_stiffness>0</spring_stiffness>
            <damping>0</damping>
            <friction>0</friction>
          </dynamics>
        </axis>
      </joint>
      <link name='wheel_right_link'>
        <pose>0.47631397208144133 -0.2750000000000003 1.3877787807814457e-17 0 -4.5265982231774944e-16 -0.52359877559829937</pose>
        <inertial>
          <pose>0 0 0 0 0 0</pose>
          <mass>0.5</mass>
          <inertia>
            <ixx>0.001</ixx>
            <ixy>0</ixy>
            <ixz>0</ixz>
            <iyy>0.001</iyy>
            <iyz>0</iyz>
            <izz>0.001</izz>
          </inertia>
        </inertial>
        <collision name='wheel_right_link_collision'>
          <pose>0 0 0 0 1.5707963267948966 0</pose>
          <geometry>
            <cylinder>
              <length>0.050000000000000003</length>
              <radius>0.10000000000000001</radius>
            </cylinder>
          </geometry>
          <surface>
            <friction>
              <ode/>
            </friction>
            <bounce/>
            <contact/>
          </surface>
        </collision>
        <visual name='wheel_right_link_visual'>
          <pose>0 0 0 0 1.5707963267948966 0</pose>
          <geometry>
            <cylinder>
              <length>0.050000000000000003</length>
              <radius>0.10000000000000001</radius>
            </cylinder>
          </geometry>
          <material>
            <diffuse>0.625 0.625 0.625 1</diffuse>
            <ambient>0.625 0.625 0.625 1</ambient>
          </material>
        </visual>
        <enable_wind>false</enable_wind>
      </link>
      <plugin name='gz::sim::systems::PosePublisher' filename='gz-sim-pose-publisher-system'>
        <update_frequency>10</update_frequency>
        <publish_model_pose>true</publish_model_pose>
        <publish_link_pose>false</publish_link_pose>
        <use_pose_vector_msg>true</use_pose_vector_msg>
      </plugin>
      <frame name='base_joint' attached_to='base_footprint'>
        <pose>0 0 0 0 0 0</pose>
      </frame>
      <frame name='base_link' attached_to='base_joint'>
        <pose>0 0 0 0 0 0</pose>
      </frame>
      <pose>4 6.1437560136031299e-17 0.099999895738787647 1.5556465607258881e-16 1.2213065887778763e-16 -4.4732955363115538e-18</pose>
      <static>false</static>
      <self_collide>false</self_collide>
    </model>
    <model name='robot2'>
      <link name='base_footprint'>
        <inertial>
          <pose>0 0 0.10000000000000001 0 0 0</pose>
          <mass>1</mass>
          <inertia>
            <ixx>0.093333333333333324</ixx>
            <ixy>0</ixy>
            <ixz>0</ixz>
            <iyy>0.093333333333333324</iyy>
            <iyz>0</iyz>
            <izz>0.17999999999999999</izz>
          </inertia>
        </inertial>
        <collision name='base_footprint_fixed_joint_lump__base_link_collision'>
          <pose>0 0 0.10000000000000001 0 0 0</pose>
          <geometry>
            <cylinder>
              <length>0.20000000000000001</length>
              <radius>0.59999999999999998</radius>
            </cylinder>
          </geometry>
          <surface>
            <friction>
              <ode/>
            </friction>
            <bounce/>
            <contact/>
          </surface>
        </collision>
        <visual name='base_footprint_fixed_joint_lump__base_link_visual'>
          <pose>0 0 0.10000000000000001 0 0 0</pose>
          <geometry>
            <cylinder>
              <length>0.20000000000000001</length>
              <radius>0.59999999999999998</radius>
            </cylinder>
          </geometry>
          <material>
            <diffuse>0 1 0 1</diffuse>
            <ambient>0 1 0 1</ambient>
          </material>
        </visual>
        <pose>0 0 0 0 0 0</pose>
        <enable_wind>false</enable_wind>
      </link>
      <joint name='wheel_front_joint' type='revolute'>
        <pose>0 0 0 0 0 0</pose>
        <parent>base_footprint</parent>
        <child>wheel_front_link</child>
        <axis>
          <xyz>0 1 0</xyz>
          <limit>
            <lower>-inf</lower>
            <upper>inf</upper>
            <effort>inf</effort>
            <velocity>inf</velocity>
            <stiffness>100000000</stiffness>
            <dissipation>1</dissipation>
          </limit>
          <dynamics>
            <spring_reference>0</spring_reference>
            <spring_stiffness>0</spring_stiffness>
            <damping>0</damping>
            <friction>0</friction>
          </dynamics>
        </axis>
      </joint>
      <link name='wheel_front_link'>
        <pose>0 0.54999999999999993 1.3877787807814457e-17 0 5.9321098920497913e-16 1.5707963267948959</pose>
        <inertial>
          <pose>0 0 0 0 0 0</pose>
          <mass>0.5</mass>
          <inertia>
            <ixx>0.001</ixx>
            <ixy>0</ixy>
            <ixz>0</ixz>
            <iyy>0.001</iyy>
            <iyz>0</iyz>
            <izz>0.001</izz>
          </inertia>
        </inertial>
        <collision name='wheel_front_link_collision'>
          <pose>0 0 0 0 1.5707963267948966 0</pose>
          <geometry>
            <cylinder>
              <length>0.050000000000000003</length>
              <radius>0.10000000000000001</radius>
            </cylinder>
          </geometry>
          <surface>
            <friction>
              <ode/>
            </friction>
            <bounce/>
            <contact/>
          </surface>
        </collision>
        <visual name='wheel_front_link_visual'>
          <pose>0 0 0 0 1.5707963267948966 0</pose>
          <geometry>
            <cylinder>
              <length>0.050000000000000003</length>
              <radius>0.10000000000000001</radius>
            </cylinder>
          </geometry>
          <material>
            <diffuse>0.625 0.625 0.625 1</diffuse>
            <ambient>0.625 0.625 0.625 1</ambient>
          </material>
        </visual>
        <enable_wind>false</enable_wind>
      </link>
      <joint name='wheel_left_joint' type='revolute'>
        <pose>0 -2.7755575615628914e-17 0 0 0 0</pose>
        <parent>base_footprint</parent>
        <child>wheel_left_link</child>
        <axis>
          <xyz>0 1 0</xyz>
          <limit>
            <lower>-inf</lower>
            <upper>inf</upper>
            <effort>inf</effort>
            <velocity>inf</velocity>
            <stiffness>100000000</stiffness>
            <dissipation>1</dissipation>
          </limit>
          <dynamics>
            <spring_reference>0</spring_reference>
            <spring_stiffness>0</spring_stiffness>
            <damping>0</damping>
            <friction>0</friction>
          </dynamics>
        </axis>
      </joint>
      <link name='wheel_left_link'>
        <pose>-0.47631397208144133 -0.27500000000000013 0 2.4651903288156619e-32 -4.3512167354894154e-16 -2.617993877991494</pose>
        <inertial>
          <pose>0 0 0 0 0 0</pose>
          <mass>0.5</mass>
          <inertia>
            <ixx>0.001</ixx>
            <ixy>0</ixy>
            <ixz>0</ixz>
            <iyy>0.001</iyy>
            <iyz>0</iyz>
            <izz>0.001</izz>
          </inertia>
        </inertial>
        <collision name='wheel_left_link_collision'>
          <pose>0 0 0 0 1.5707963267948966 0</pose>
          <geometry>
            <cylinder>
              <length>0.050000000000000003</length>
              <radius>0.10000000000000001</radius>
            </cylinder>
          </geometry>
          <surface>
            <friction>
              <ode/>
            </friction>
            <bounce/>
            <contact/>
          </surface>
        </collision>
        <visual name='wheel_left_link_visual'>
          <pose>0 0 0 0 1.5707963267948966 0</pose>
          <geometry>
            <cylinder>
              <length>0.050000000000000003</length>
              <radius>0.10000000000000001</radius>
            </cylinder>
          </geometry>
          <material>
            <diffuse>0.625 0.625 0.625 1</diffuse>
            <ambient>0.625 0.625 0.625 1</ambient>
          </material>
        </visual>
        <enable_wind>false</enable_wind>
      </link>
      <joint name='wheel_right_joint' type='revolute'>
        <pose>1.1102230246251565e-16 2.7755575615628914e-17 0 0 0 0</pose>
        <parent>base_footprint</parent>
        <child>wheel_right_link</child>
        <axis>
          <xyz>0 1 0</xyz>
          <limit>
            <lower>-inf</lower>
            <upper>inf</upper>
            <effort>inf</effort>
            <velocity>inf</velocity>
            <stiffness>100000000</stiffness>
            <dissipation>1</dissipation>
          </limit>
          <dynamics>
            <spring_reference>0</spring_reference>
            <spring_stiffness>0</spring_stiffness>
            <damping>0</damping>
            <friction>0</friction>
          </dynamics>
        </axis>
      </joint>
      <link name='wheel_right_link'>
        <pose>0.47631397208144133 -0.27500000000000002 0 4.3140830754274083e-32 -1.6222935891560731e-16 -0.52359877559829937</pose>
        <inertial>
          <pose>0 0 0 0 0 0</pose>
          <mass>0.5</mass>
          <inertia>
            <ixx>0.001</ixx>
            <ixy>0</ixy>
            <ixz>0</ixz>
            <iyy>0.001</iyy>
            <iyz>0</iyz>
            <izz>0.001</izz>
          </inertia>
        </inertial>
        <collision name='wheel_right_link_collision'>
          <pose>0 0 0 0 1.5707963267948966 0</pose>
          <geometry>
            <cylinder>
              <length>0.050000000000000003</length>
              <radius>0.10000000000000001</radius>
            </cylinder>
          </geometry>
          <surface>
            <friction>
              <ode/>
            </friction>
            <bounce/>
            <contact/>
          </surface>
        </collision>
        <visual name='wheel_right_link_visual'>
          <pose>0 0 0 0 1.5707963267948966 0</pose>
          <geometry>
            <cylinder>
              <length>0.050000000000000003</length>
              <radius>0.10000000000000001</radius>
            </cylinder>
          </geometry>
          <material>
            <diffuse>0.625 0.625 0.625 1</diffuse>
            <ambient>0.625 0.625 0.625 1</ambient>
          </material>
        </visual>
        <enable_wind>false</enable_wind>
      </link>
      <plugin name='gz::sim::systems::PosePublisher' filename='gz-sim-pose-publisher-system'>
        <update_frequency>10</update_frequency>
        <publish_model_pose>true</publish_model_pose>
        <publish_link_pose>false</publish_link_pose>
        <use_pose_vector_msg>true</use_pose_vector_msg>
      </plugin>
      <frame name='base_joint' attached_to='base_footprint'>
        <pose>0 0 0 0 0 0</pose>
      </frame>
      <frame name='base_link' attached_to='base_joint'>
        <pose>0 0 0 0 0 0</pose>
      </frame>
      <pose>2 4.1601021363559795e-17 0.099999895738787634 2.7315624720185862e-16 -1.5134524313517485e-16 -2.8423757208361146e-17</pose>
      <static>false</static>
      <self_collide>false</self_collide>
    </model>
    <model name='robot1'>
      <link name='base_footprint'>
        <inertial>
          <pose>0 0 0.10000000000000001 0 0 0</pose>
          <mass>1</mass>
          <inertia>
            <ixx>0.093333333333333324</ixx>
            <ixy>0</ixy>
            <ixz>0</ixz>
            <iyy>0.093333333333333324</iyy>
            <iyz>0</iyz>
            <izz>0.17999999999999999</izz>
          </inertia>
        </inertial>
        <collision name='base_footprint_fixed_joint_lump__base_link_collision'>
          <pose>0 0 0.10000000000000001 0 0 0</pose>
          <geometry>
            <cylinder>
              <length>0.20000000000000001</length>
              <radius>0.59999999999999998</radius>
            </cylinder>
          </geometry>
          <surface>
            <friction>
              <ode/>
            </friction>
            <bounce/>
            <contact/>
          </surface>
        </collision>
        <visual name='base_footprint_fixed_joint_lump__base_link_visual'>
          <pose>0 0 0.10000000000000001 0 0 0</pose>
          <geometry>
            <cylinder>
              <length>0.20000000000000001</length>
              <radius>0.59999999999999998</radius>
            </cylinder>
          </geometry>
          <material>
            <diffuse>0 1 0 1</diffuse>
            <ambient>0 1 0 1</ambient>
          </material>
        </visual>
        <pose>0 0 0 0 0 0</pose>
        <enable_wind>false</enable_wind>
      </link>
      <joint name='wheel_front_joint' type='revolute'>
        <pose>0 0 0 0 0 0</pose>
        <parent>base_footprint</parent>
        <child>wheel_front_link</child>
        <axis>
          <xyz>0 1 0</xyz>
          <limit>
            <lower>-inf</lower>
            <upper>inf</upper>
            <effort>inf</effort>
            <velocity>inf</velocity>
            <stiffness>100000000</stiffness>
            <dissipation>1</dissipation>
          </limit>
          <dynamics>
            <spring_reference>0</spring_reference>
            <spring_stiffness>0</spring_stiffness>
            <damping>0</damping>
            <friction>0</friction>
          </dynamics>
        </axis>
      </joint>
      <link name='wheel_front_link'>
        <pose>3.3677786976552219e-17 0.55000000000000004 -1.3877787807814457e-17 -4.9303806576313238e-32 6.3025492027763865e-16 1.5707963267948959</pose>
        <inertial>
          <pose>0 0 0 0 0 0</pose>
          <mass>0.5</mass>
          <inertia>
            <ixx>0.001</ixx>
            <ixy>0</ixy>
            <ixz>0</ixz>
            <iyy>0.001</iyy>
            <iyz>0</iyz>
            <izz>0.001</izz>
          </inertia>
        </inertial>
        <collision name='wheel_front_link_collision'>
          <pose>0 0 0 0 1.5707963267948966 0</pose>
          <geometry>
            <cylinder>
              <length>0.050000000000000003</length>
              <radius>0.10000000000000001</radius>
            </cylinder>
          </geometry>
          <surface>
            <friction>
              <ode/>
            </friction>
            <bounce/>
            <contact/>
          </surface>
        </collision>
        <visual name='wheel_front_link_visual'>
          <pose>0 0 0 0 1.5707963267948966 0</pose>
          <geometry>
            <cylinder>
              <length>0.050000000000000003</length>
              <radius>0.10000000000000001</radius>
            </cylinder>
          </geometry>
          <material>
            <diffuse>0.625 0.625 0.625 1</diffuse>
            <ambient>0.625 0.625 0.625 1</ambient>
          </material>
        </visual>
        <enable_wind>false</enable_wind>
      </link>
      <joint name='wheel_left_joint' type='revolute'>
        <pose>0 -2.7755575615628914e-17 0 0 0 0</pose>
        <parent>base_footprint</parent>
        <child>wheel_left_link</child>
        <axis>
          <xyz>0 1 0</xyz>
          <limit>
            <lower>-inf</lower>
            <upper>inf</upper>
            <effort>inf</effort>
            <velocity>inf</velocity>
            <stiffness>100000000</stiffness>
            <dissipation>1</dissipation>
          </limit>
          <dynamics>
            <spring_reference>0</spring_reference>
            <spring_stiffness>0</spring_stiffness>
            <damping>0</damping>
            <friction>0</friction>
          </dynamics>
        </axis>
      </joint>
      <link name='wheel_left_link'>
        <pose>-0.47631397208144127 -0.27500000000000008 0 -9.8607613152626476e-32 -9.4320501955985773e-16 -2.617993877991494</pose>
        <inertial>
          <pose>0 0 0 0 0 0</pose>
          <mass>0.5</mass>
          <inertia>
            <ixx>0.001</ixx>
            <ixy>0</ixy>
            <ixz>0</ixz>
            <iyy>0.001</iyy>
            <iyz>0</iyz>
            <izz>0.001</izz>
          </inertia>
        </inertial>
        <collision name='wheel_left_link_collision'>
          <pose>0 0 0 0 1.5707963267948966 0</pose>
          <geometry>
            <cylinder>
              <length>0.050000000000000003</length>
              <radius>0.10000000000000001</radius>
            </cylinder>
          </geometry>
          <surface>
            <friction>
              <ode/>
            </friction>
            <bounce/>
            <contact/>
          </surface>
        </collision>
        <visual name='wheel_left_link_visual'>
          <pose>0 0 0 0 1.5707963267948966 0</pose>
          <geometry>
            <cylinder>
              <length>0.050000000000000003</length>
              <radius>0.10000000000000001</radius>
            </cylinder>
          </geometry>
          <material>
            <diffuse>0.625 0.625 0.625 1</diffuse>
            <ambient>0.625 0.625 0.625 1</ambient>
          </material>
        </visual>
        <enable_wind>false</enable_wind>
      </link>
      <joint name='wheel_right_joint' type='revolute'>
        <pose>1.1102230246251565e-16 2.7755575615628914e-17 0 0 0 0</pose>
        <parent>base_footprint</parent>
        <child>wheel_right_link</child>
        <axis>
          <xyz>0 1 0</xyz>
          <limit>
            <lower>-inf</lower>
            <upper>inf</upper>
            <effort>inf</effort>
            <velocity>inf</velocity>
            <stiffness>100000000</stiffness>
            <dissipation>1</dissipation>
          </limit>
          <dynamics>
            <spring_reference>0</spring_reference>
            <spring_stiffness>0</spring_stiffness>
            <damping>0</damping>
            <friction>0</friction>
          </dynamics>
        </axis>
      </joint>
      <link name='wheel_right_link'>
        <pose>0.47631397208144122 -0.2750000000000003 -1.3877787807814457e-17 1.9259299443872359e-32 -1.658749687298532e-17 -0.52359877559829926</pose>
        <inertial>
          <pose>0 0 0 0 0 0</pose>
          <mass>0.5</mass>
          <inertia>
            <ixx>0.001</ixx>
            <ixy>0</ixy>
            <ixz>0</ixz>
            <iyy>0.001</iyy>
            <iyz>0</iyz>
            <izz>0.001</izz>
          </inertia>
        </inertial>
        <collision name='wheel_right_link_collision'>
          <pose>0 0 0 0 1.5707963267948966 0</pose>
          <geometry>
            <cylinder>
              <length>0.050000000000000003</length>
              <radius>0.10000000000000001</radius>
            </cylinder>
          </geometry>
          <surface>
            <friction>
              <ode/>
            </friction>
            <bounce/>
            <contact/>
          </surface>
        </collision>
        <visual name='wheel_right_link_visual'>
          <pose>0 0 0 0 1.5707963267948966 0</pose>
          <geometry>
            <cylinder>
              <length>0.050000000000000003</length>
              <radius>0.10000000000000001</radius>
            </cylinder>
          </geometry>
          <material>
            <diffuse>0.625 0.625 0.625 1</diffuse>
            <ambient>0.625 0.625 0.625 1</ambient>
          </material>
        </visual>
        <enable_wind>false</enable_wind>
      </link>
      <plugin name='gz::sim::systems::PosePublisher' filename='gz-sim-pose-publisher-system'>
        <update_frequency>10</update_frequency>
        <publish_model_pose>true</publish_model_pose>
        <publish_link_pose>false</publish_link_pose>
        <use_pose_vector_msg>true</use_pose_vector_msg>
      </plugin>
      <frame name='base_joint' attached_to='base_footprint'>
        <pose>0 0 0 0 0 0</pose>
      </frame>
      <frame name='base_link' attached_to='base_joint'>
        <pose>0 0 0 0 0 0</pose>
      </frame>
      <pose>-5.7702503273477178e-18 1.8276019308852019e-17 0.099999895738787634 2.3135000957562616e-16 -5.3400512515644643e-17 -6.113670521710789e-17</pose>
      <static>false</static>
      <self_collide>false</self_collide>
    </model>
    <light name='sun' type='directional'>
      <pose>0 0 10 0 0 0</pose>
      <cast_shadows>true</cast_shadows>
      <intensity>1</intensity>
      <direction>-0.5 0.10000000000000001 -0.90000000000000002</direction>
      <diffuse>0.800000012 0.800000012 0.800000012 1</diffuse>
      <specular>0.200000003 0.200000003 0.200000003 1</specular>
      <attenuation>
        <range>1000</range>
        <linear>0.01</linear>
        <constant>0.90000000000000002</constant>
        <quadratic>0.001</quadratic>
      </attenuation>
      <spot>
        <inner_angle>0</inner_angle>
        <outer_angle>0</outer_angle>
        <falloff>0</falloff>
      </spot>
    </light>
  </world>
</sdf>
